Workbook
Name AcceptedCmp1: 'Data Cleaning'!$AE$2:$AE$2237
Name AcceptedCmp2: 'Data Cleaning'!$AF$2:$AF$2237
Name AcceptedCmp3: 'Data Cleaning'!$AB$2:$AB$2237
Name AcceptedCmp4: 'Data Cleaning'!$AC$2:$AC$2237
Name AcceptedCmp5: 'Data Cleaning'!$AD$2:$AD$2237
Name Age: 'Data Cleaning'!$C$2:$C$2237
Name Age_Group: 'Data Cleaning'!$D$2:$D$2237
Name Complain: 'Data Cleaning'!$AH$2:$AH$2237
Name Dt_Customer: 'Data Cleaning'!$N$2:$N$2237
Name Education: 'Data Cleaning'!$E$2:$E$2237
Name HasChildren: 'Data Cleaning'!$M$2:$M$2237
Name ID: 'Data Cleaning'!$A$2:$A$2237
Name Income: 'Data Cleaning'!$G$2:$G$2237
Name Income_Clean: 'Data Cleaning'!$H$2:$H$2237
Name Income_Segment: 'Data Cleaning'!$I$2:$I$2237
Name Kidhome: 'Data Cleaning'!$K$2:$K$2237
Name Marital_Status: 'Data Cleaning'!$F$2:$F$2237
Name MntFishProducts: 'Data Cleaning'!$S$2:$S$2237
Name MntFruits: 'Data Cleaning'!$Q$2:$Q$2237
Name MntGoldProds: 'Data Cleaning'!$U$2:$U$2237
Name MntMeatProducts: 'Data Cleaning'!$R$2:$R$2237
Name MntSweetProducts: 'Data Cleaning'!$T$2:$T$2237
Name MntWines: 'Data Cleaning'!$P$2:$P$2237
Name NumCatalogPurchases: 'Data Cleaning'!$Y$2:$Y$2237
Name NumDealsPurchases: 'Data Cleaning'!$W$2:$W$2237
Name NumStorePurchases: 'Data Cleaning'!$Z$2:$Z$2237
Name NumWebPurchases: 'Data Cleaning'!$X$2:$X$2237
Name NumWebVisitsMonth: 'Data Cleaning'!$AA$2:$AA$2237
Name Recency: 'Data Cleaning'!$O$2:$O$2237
Name Response: 'Data Cleaning'!$AI$2:$AI$2237
Name Slicer_Age_Group: #N/A
Name Slicer_Income_Segment: #N/A
Name Teenhome: 'Data Cleaning'!$L$2:$L$2237
Name TotalCampaigns: 'Data Cleaning'!$AG$2:$AG$2237
Name TotalSpend: 'Data Cleaning'!$V$2:$V$2237
Name Year_Birth: 'Data Cleaning'!$B$2:$B$2237

Sheet Raw Data
A1: ID | B1: Year_Birth | C1: Education | D1: Marital_Status | E1: Income | F1: Kidhome | G1: Teenhome | H1: Dt_Customer | I1: Recency | J1: MntWines | K1: MntFruits | L1: MntMeatProducts | M1: MntFishProducts | N1: MntSweetProducts | O1: MntGoldProds | P1: NumDealsPurchases | Q1: NumWebPurchases | R1: NumCatalogPurchases | S1: NumStorePurchases | T1: NumWebVisitsMonth | U1: AcceptedCmp3 | V1: AcceptedCmp4 | W1: AcceptedCmp5 | X1: AcceptedCmp1 | Y1: AcceptedCmp2 | Z1: Complain | AA1: Z_CostContact | AB1: Z_Revenue | AC1: Response
A2: 5524 | B2: 1957 | C2: Graduation | D2: Single | E2: 58138 | F2: 0 | G2: 0 | H2: 2012-09-04 | I2: 58 | J2: 635 | K2: 88 | L2: 546 | M2: 172 | N2: 88 | O2: 88 | P2: 3 | Q2: 8 | R2: 10 | S2: 4 | T2: 7 | U2: 0 | V2: 0 | W2: 0 | X2: 0 | Y2: 0 | Z2: 0 | AA2: 3 | AB2: 11 | AC2: 1
A3: 2174 | B3: 1954 | C3: Graduation | D3: Single | E3: 46344 | F3: 1 | G3: 1 | H3: 2014-03-08 | I3: 38 | J3: 11 | K3: 1 | L3: 6 | M3: 2 | N3: 1 | O3: 6 | P3: 2 | Q3: 1 | R3: 1 | S3: 2 | T3: 5 | U3: 0 | V3: 0 | W3: 0 | X3: 0 | Y3: 0 | Z3: 0 | AA3: 3 | AB3: 11 | AC3: 0
A4: 4141 | B4: 1965 | C4: Graduation | D4: Together | E4: 71613 | F4: 0 | G4: 0 | H4: 2013-08-21 | I4: 26 | J4: 426 | K4: 49 | L4: 127 | M4: 111 | N4: 21 | O4: 42 | P4: 1 | Q4: 8 | R4: 2 | S4: 10 | T4: 4 | U4: 0 | V4: 0 | W4: 0 | X4: 0 | Y4: 0 | Z4: 0 | AA4: 3 | AB4: 11 | AC4: 0
A5: 6182 | B5: 1984 | C5: Graduation | D5: Together | E5: 26646 | F5: 1 | G5: 0 | H5: 2014-02-10 | I5: 26 | J5: 11 | K5: 4 | L5: 20 | M5: 10 | N5: 3 | O5: 5 | P5: 2 | Q5: 2 | R5: 0 | S5: 4 | T5: 6 | U5: 0 | V5: 0 | W5: 0 | X5: 0 | Y5: 0 | Z5: 0 | AA5: 3 | AB5: 11 | AC5: 0
A6: 5324 | B6: 1981 | C6: PhD | D6: Married | E6: 58293 | F6: 1 | G6: 0 | H6: 2014-01-19 | I6: 94 | J6: 173 | K6: 43 | L6: 118 | M6: 46 | N6: 27 | O6: 15 | P6: 5 | Q6: 5 | R6: 3 | S6: 6 | T6: 5 | U6: 0 | V6: 0 | W6: 0 | X6: 0 | Y6: 0 | Z6: 0 | AA6: 3 | AB6: 11 | AC6: 0
A7: 7446 | B7: 1967 | C7: Master | D7: Together | E7: 62513 | F7: 0 | G7: 1 | H7: 2013-09-09 | I7: 16 | J7: 520 | K7: 42 | L7: 98 | M7: 0 | N7: 42 | O7: 14 | P7: 2 | Q7: 6 | R7: 4 | S7: 10 | T7: 6 | U7: 0 | V7: 0 | W7: 0 | X7: 0 | Y7: 0 | Z7: 0 | AA7: 3 | AB7: 11 | AC7: 0
A8: 965 | B8: 1971 | C8: Graduation | D8: Divorced | E8: 55635 | F8: 0 | G8: 1 | H8: 2012-11-13 | I8: 34 | J8: 235 | K8: 65 | L8: 164 | M8: 50 | N8: 49 | O8: 27 | P8: 4 | Q8: 7 | R8: 3 | S8: 7 | T8: 6 | U8: 0 | V8: 0 | W8: 0 | X8: 0 | Y8: 0 | Z8: 0 | AA8: 3 | AB8: 11 | AC8: 0
A9: 6177 | B9: 1985 | C9: PhD | D9: Married | E9: 33454 | F9: 1 | G9: 0 | H9: 2013-05-08 | I9: 32 | J9: 76 | K9: 10 | L9: 56 | M9: 3 | N9: 1 | O9: 23 | P9: 2 | Q9: 4 | R9: 0 | S9: 4 | T9: 8 | U9: 0 | V9: 0 | W9: 0 | X9: 0 | Y9: 0 | Z9: 0 | AA9: 3 | AB9: 11 | AC9: 0
A10: 4855 | B10: 1974 | C10: PhD | D10: Together | E10: 30351 | F10: 1 | G10: 0 | H10: 2013-06-06 | I10: 19 | J10: 14 | K10: 0 | L10: 24 | M10: 3 | N10: 3 | O10: 2 | P10: 1 | Q10: 3 | R10: 0 | S10: 2 | T10: 9 | U10: 0 | V10: 0 | W10: 0 | X10: 0 | Y10: 0 | Z10: 0 | AA10: 3 | AB10: 11 | AC10: 1
A11: 5899 | B11: 1950 | C11: PhD | D11: Together | E11: 5648 | F11: 1 | G11: 1 | H11: 2014-03-13 | I11: 68 | J11: 28 | K11: 0 | L11: 6 | M11: 1 | N11: 1 | O11: 13 | P11: 1 | Q11: 1 | R11: 0 | S11: 0 | T11: 20 | U11: 1 | V11: 0 | W11: 0 | X11: 0 | Y11: 0 | Z11: 0 | AA11: 3 | AB11: 11 | AC11: 0
A12: 1994 | B12: 1983 | C12: Graduation | D12: Married | F12: 1 | G12: 0 | H12: 2013-11-15 | I12: 11 | J12: 5 | K12: 5 | L12: 6 | M12: 0 | N12: 2 | O12: 1 | P12: 1 | Q12: 1 | R12: 0 | S12: 2 | T12: 7 | U12: 0 | V12: 0 | W12: 0 | X12: 0 | Y12: 0 | Z12: 0 | AA12: 3 | AB12: 11 | AC12: 0
A13: 387 | B13: 1976 | C13: Basic | D13: Married | E13: 7500 | F13: 0 | G13: 0 | H13: 2012-11-13 | I13: 59 | J13: 6 | K13: 16 | L13: 11 | M13: 11 | N13: 1 | O13: 16 | P13: 1 | Q13: 2 | R13: 0 | S13: 3 | T13: 8 | U13: 0 | V13: 0 | W13: 0 | X13: 0 | Y13: 0 | Z13: 0 | AA13: 3 | AB13: 11 | AC13: 0
A14: 2125 | B14: 1959 | C14: Graduation | D14: Divorced | E14: 63033 | F14: 0 | G14: 0 | H14: 2013-11-15 | I14: 82 | J14: 194 | K14: 61 | L14: 480 | M14: 225 | N14: 112 | O14: 30 | P14: 1 | Q14: 3 | R14: 4 | S14: 8 | T14: 2 | U14: 0 | V14: 0 | W14: 0 | X14: 0 | Y14: 0 | Z14: 0 | AA14: 3 | AB14: 11 | AC14: 0
A15: 8180 | B15: 1952 | C15: Master | D15: Divorced | E15: 59354 | F15: 1 | G15: 1 | H15: 2013-11-15 | I15: 53 | J15: 233 | K15: 2 | L15: 53 | M15: 3 | N15: 5 | O15: 14 | P15: 3 | Q15: 6 | R15: 1 | S15: 5 | T15: 6 | U15: 0 | V15: 0 | W15: 0 | X15: 0 | Y15: 0 | Z15: 0 | AA15: 3 | AB15: 11 | AC15: 0
A16: 2569 | B16: 1987 | C16: Graduation | D16: Married | E16: 17323 | F16: 0 | G16: 0 | H16: 2012-10-10 | I16: 38 | J16: 3 | K16: 14 | L16: 17 | M16: 6 | N16: 1 | O16: 5 | P16: 1 | Q16: 1 | R16: 0 | S16: 3 | T16: 8 | U16: 0 | V16: 0 | W16: 0 | X16: 0 | Y16: 0 | Z16: 0 | AA16: 3 | AB16: 11 | AC16: 0
A17: 2114 | B17: 1946 | C17: PhD | D17: Single | E17: 82800 | F17: 0 | G17: 0 | H17: 2012-11-24 | I17: 23 | J17: 1006 | K17: 22 | L17: 115 | M17: 59 | N17: 68 | O17: 45 | P17: 1 | Q17: 7 | R17: 6 | S17: 12 | T17: 3 | U17: 0 | V17: 0 | W17: 1 | X17: 1 | Y17: 0 | Z17: 0 | AA17: 3 | AB17: 11 | AC17: 1
A18: 9736 | B18: 1980 | C18: Graduation | D18: Married | E18: 41850 | F18: 1 | G18: 1 | H18: 2012-12-24 | I18: 51 | J18: 53 | K18: 5 | L18: 19 | M18: 2 | N18: 13 | O18: 4 | P18: 3 | Q18: 3 | R18: 0 | S18: 3 | T18: 8 | U18: 0 | V18: 0 | W18: 0 | X18: 0 | Y18: 0 | Z18: 0 | AA18: 3 | AB18: 11 | AC18: 0
A19: 4939 | B19: 1946 | C19: Graduation | D19: Together | E19: 37760 | F19: 0 | G19: 0 | H19: 2012-08-31 | I19: 20 | J19: 84 | K19: 5 | L19: 38 | M19: 150 | N19: 12 | O19: 28 | P19: 2 | Q19: 4 | R19: 1 | S19: 6 | T19: 7 | U19: 0 | V19: 0 | W19: 0 | X19: 0 | Y19: 0 | Z19: 0 | AA19: 3 | AB19: 11 | AC19: 0
A20: 6565 | B20: 1949 | C20: Master | D20: Married | E20: 76995 | F20: 0 | G20: 1 | H20: 2013-03-28 | I20: 91 | J20: 1012 | K20: 80 | L20: 498 | M20: 0 | N20: 16 | O20: 176 | P20: 2 | Q20: 11 | R20: 4 | S20: 9 | T20: 5 | U20: 0 | V20: 0 | W20: 0 | X20: 1 | Y20: 0 | Z20: 0 | AA20: 3 | AB20: 11 | AC20: 0
A21: 2278 | B21: 1985 | C21: 2n Cycle | D21: Single | E21: 33812 | F21: 1 | G21: 0 | H21: 2012-11-03 | I21: 86 | J21: 4 | K21: 17 | L21: 19 | M21: 30 | N21: 24 | O21: 39 | P21: 2 | Q21: 2 | R21: 1 | S21: 3 | T21: 6 | U21: 0 | V21: 0 | W21: 0 | X21: 0 | Y21: 0 | Z21: 0 | AA21: 3 | AB21: 11 | AC21: 0
A22: 9360 | B22: 1982 | C22: Graduation | D22: Married | E22: 37040 | F22: 0 | G22: 0 | H22: 2012-08-08 | I22: 41 | J22: 86 | K22: 2 | L22: 73 | M22: 69 | N22: 38 | O22: 48 | P22: 1 | Q22: 4 | R22: 2 | S22: 5 | T22: 8 | U22: 0 | V22: 0 | W22: 0 | X22: 0 | Y22: 0 | Z22: 0 | AA22: 3 | AB22: 11 | AC22: 0
A23: 5376 | B23: 1979 | C23: Graduation | D23: Married | E23: 2447 | F23: 1 | G23: 0 | H23: 2013-01-06 | I23: 42 | J23: 1 | K23: 1 | L23: 1725 | M23: 1 | N23: 1 | O23: 1 | P23: 15 | Q23: 0 | R23: 28 | S23: 0 | T23: 1 | U23: 0 | V23: 0 | W23: 0 | X23: 0 | Y23: 0 | Z23: 0 | AA23: 3 | AB23: 11 | AC23: 0
A24: 1993 | B24: 1949 | C24: PhD | D24: Married | E24: 58607 | F24: 0 | G24: 1 | H24: 2012-12-23 | I24: 63 | J24: 867 | K24: 0 | L24: 86 | M24: 0 | N24: 0 | O24: 19 | P24: 3 | Q24: 2 | R24: 3 | S24: 9 | T24: 8 | U24: 0 | V24: 1 | W24: 0 | X24: 0 | Y24: 0 | Z24: 0 | AA24: 3 | AB24: 11 | AC24: 0
... A28: 2404 | B28: 1976 | C28: Graduation | D28: Married | E28: 53359 | F28: 1 | G28: 1 | H28: 2013-05-27 | I28: 4 | J28: 173 | K28: 4 | L28: 30 | M28: 3 | N28: 6 | O28: 41 | P28: 4 | Q28: 5 | R28: 1 | S28: 4 | T28: 7 | U28: 0 | V28: 0 | W28: 0 | X28: 0 | Y28: 0 | Z28: 0 | AA28: 3 | AB28: 11 | AC28: 0
A29: 5255 | B29: 1986 | C29: Graduation | D29: Single | F29: 1 | G29: 0 | H29: 2013-02-20 | I29: 19 | J29: 5 | K29: 1 | L29: 3 | M29: 3 | N29: 263 | O29: 362 | P29: 0 | Q29: 27 | R29: 0 | S29: 0 | T29: 1 | U29: 0 | V29: 0 | W29: 0 | X29: 0 | Y29: 0 | Z29: 0 | AA29: 3 | AB29: 11 | AC29: 0
A30: 9422 | B30: 1989 | C30: Graduation | D30: Married | E30: 38360 | F30: 1 | G30: 0 | H30: 2013-05-31 | I30: 26 | J30: 36 | K30: 2 | L30: 42 | M30: 20 | N30: 21 | O30: 10 | P30: 2 | Q30: 2 | R30: 1 | S30: 4 | T30: 3 | U30: 0 | V30: 0 | W30: 0 | X30: 0 | Y30: 0 | Z30: 0 | AA30: 3 | AB30: 11 | AC30: 0
A31: 1966 | B31: 1965 | C31: PhD | D31: Married | E31: 84618 | F31: 0 | G31: 0 | H31: 2013-11-22 | I31: 96 | J31: 684 | K31: 100 | L31: 801 | M31: 21 | N31: 66 | O31: 0 | P31: 1 | Q31: 6 | R31: 9 | S31: 10 | T31: 2 | U31: 0 | V31: 0 | W31: 1 | X31: 0 | Y31: 0 | Z31: 0 | AA31: 3 | AB31: 11 | AC31: 0
A32: 6864 | B32: 1989 | C32: Master | D32: Divorced | E32: 10979 | F32: 0 | G32: 0 | H32: 2014-05-22 | I32: 34 | J32: 8 | K32: 4 | L32: 10 | M32: 2 | N32: 2 | O32: 4 | P32: 2 | Q32: 3 | R32: 0 | S32: 3 | T32: 5 | U32: 0 | V32: 0 | W32: 0 | X32: 0 | Y32: 0 | Z32: 0 | AA32: 3 | AB32: 11 | AC32: 0
A33: 3033 | B33: 1963 | C33: Master | D33: Together | E33: 38620 | F33: 0 | G33: 0 | H33: 2013-05-11 | I33: 56 | J33: 112 | K33: 17 | L33: 44 | M33: 34 | N33: 22 | O33: 89 | P33: 1 | Q33: 2 | R33: 5 | S33: 3 | T33: 3 | U33: 0 | V33: 0 | W33: 0 | X33: 0 | Y33: 0 | Z33: 0 | AA33: 3 | AB33: 11 | AC33: 0
A34: 5710 | B34: 1970 | C34: Graduation | D34: Together | E34: 40548 | F34: 0 | G34: 1 | H34: 2012-10-10 | I34: 31 | J34: 110 | K34: 0 | L34: 5 | M34: 2 | N34: 0 | O34: 3 | P34: 2 | Q34: 2 | R34: 1 | S34: 4 | T34: 5 | U34: 0 | V34: 1 | W34: 0 | X34: 0 | Y34: 0 | Z34: 0 | AA34: 3 | AB34: 11 | AC34: 0
A35: 7373 | B35: 1952 | C35: PhD | D35: Divorced | E35: 46610 | F35: 0 | G35: 2 | H35: 2012-10-29 | I35: 8 | J35: 96 | K35: 12 | L35: 96 | M35: 33 | N35: 22 | O35: 43 | P35: 6 | Q35: 4 | R35: 1 | S35: 6 | T35: 6 | U35: 0 | V35: 0 | W35: 0 | X35: 0 | Y35: 0 | Z35: 0 | AA35: 3 | AB35: 11 | AC35: 1
A36: 8755 | B36: 1946 | C36: Master | D36: Married | E36: 68657 | F36: 0 | G36: 0 | H36: 2013-02-20 | I36: 4 | J36: 482 | K36: 34 | L36: 471 | M36: 119 | N36: 68 | O36: 22 | P36: 1 | Q36: 3 | R36: 5 | S36: 9 | T36: 7 | U36: 0 | V36: 0 | W36: 0 | X36: 0 | Y36: 0 | Z36: 0 | AA36: 3 | AB36: 11 | AC36: 0
A37: 10738 | B37: 1951 | C37: Master | D37: Single | E37: 49389 | F37: 1 | G37: 1 | H37: 2013-08-29 | I37: 55 | J37: 40 | K37: 0 | L37: 19 | M37: 2 | N37: 1 | O37: 3 | P37: 1 | Q37: 2 | R37: 0 | S37: 3 | T37: 7 | U37: 0 | V37: 0 | W37: 0 | X37: 0 | Y37: 0 | Z37: 0 | AA37: 3 | AB37: 11 | AC37: 0
A38: 4339 | B38: 1970 | C38: PhD | D38: Married | E38: 67353 | F38: 0 | G38: 1 | H38: 2013-12-31 | I38: 37 | J38: 702 | K38: 17 | L38: 151 | M38: 0 | N38: 8 | O38: 35 | P38: 5 | Q38: 5 | R38: 6 | S38: 12 | T38: 2 | U38: 0 | V38: 0 | W38: 0 | X38: 0 | Y38: 0 | Z38: 0 | AA38: 3 | AB38: 11 | AC38: 0
A39: 10755 | B39: 1976 | C39: 2n Cycle | D39: Married | E39: 23718 | F39: 1 | G39: 0 | H39: 2013-09-02 | I39: 76 | J39: 6 | K39: 3 | L39: 14 | M39: 15 | N39: 7 | O39: 36 | P39: 3 | Q39: 3 | R39: 1 | S39: 2 | T39: 7 | U39: 0 | V39: 0 | W39: 0 | X39: 0 | Y39: 0 | Z39: 0 | AA39: 3 | AB39: 11 | AC39: 0
A40: 8595 | B40: 1973 | C40: Graduation | D40: Widow | E40: 42429 | F40: 0 | G40: 1 | H40: 2014-02-11 | I40: 99 | J40: 55 | K40: 0 | L40: 6 | M40: 2 | N40: 0 | O40: 4 | P40: 2 | Q40: 1 | R40: 1 | S40: 3 | T40: 5 | U40: 0 | V40: 0 | W40: 0 | X40: 0 | Y40: 0 | Z40: 0 | AA40: 3 | AB40: 11 | AC40: 0
A41: 2968 | B41: 1943 | C41: PhD | D41: Divorced | E41: 48948 | F41: 0 | G41: 0 | H41: 2013-02-01 | I41: 53 | J41: 437 | K41: 8 | L41: 206 | M41: 160 | N41: 49 | O41: 42 | P41: 2 | Q41: 7 | R41: 10 | S41: 5 | T41: 6 | U41: 1 | V41: 0 | W41: 0 | X41: 0 | Y41: 0 | Z41: 0 | AA41: 3 | AB41: 11 | AC41: 1
... A44: 8430 | B44: 1957 | C44: Graduation | D44: Together | E44: 21994 | F44: 0 | G44: 1 | H44: 2012-12-24 | I44: 4 | J44: 9 | K44: 0 | L44: 6 | M44: 3 | N44: 1 | O44: 3 | P44: 1 | Q44: 0 | R44: 0 | S44: 3 | T44: 5 | U44: 0 | V44: 0 | W44: 0 | X44: 0 | Y44: 0 | Z44: 0 | AA44: 3 | AB44: 11 | AC44: 0
A45: 7281 | B45: 1959 | C45: PhD | D45: Single | F45: 0 | G45: 0 | H45: 2013-11-05 | I45: 80 | J45: 81 | K45: 11 | L45: 50 | M45: 3 | N45: 2 | O45: 39 | P45: 1 | Q45: 1 | R45: 3 | S45: 4 | T45: 2 | U45: 0 | V45: 0 | W45: 0 | X45: 0 | Y45: 0 | Z45: 0 | AA45: 3 | AB45: 11 | AC45: 0
...

Sheet Data Cleaning
A1: ID | B1: Year_Birth | C1: Age | D1: Age_Group | E1: Education | F1: Marital_Status | G1: Income | H1: Income_Clean | I1: Income_Segment | J1: Income_Label | K1: Kidhome | L1: Teenhome | M1: HasChildren | N1: Dt_Customer | O1: Recency | P1: MntWines | Q1: MntFruits | R1: MntMeatProducts | S1: MntFishProducts | T1: MntSweetProducts | U1: MntGoldProds | V1: TotalSpend | W1: NumDealsPurchases | X1: NumWebPurchases | Y1: NumCatalogPurchases | Z1: NumStorePurchases | AA1: NumWebVisitsMonth | AB1: AcceptedCmp3 | AC1: AcceptedCmp4 | AD1: AcceptedCmp5 | AE1: AcceptedCmp1 | AF1: AcceptedCmp2 | AG1: TotalCampaigns | AH1: Complain | AI1: Response
A2: 5524 | B2: 1957 | C2: =2026-B2 -> 69 | D2: {=_xlfn.IFS(C2<36,"Young",C2<56,"Middle-aged",C2>=56,"Senior")} -> Senior | E2: Graduation | F2: Single | G2: 58138 | H2: =IF(G2=0,MEDIAN(Income),G2) -> 58138 | I2: {=_xlfn.IFS(H2<PERCENTILE(Income_Clean,0.33),"Low",H2<PERCENTILE(Income_Clean,0.67),"Medium",H2>PERCENTILE(Income_Clean,0.67),"High")} -> Medium | J2: =_xlfn.XLOOKUP(I2,$AK$3:$AK$5,$AL$3:$AL$5) -> Average Income | K2: 0 | L2: 0 | M2: =IF(K2+L2>0,"Yes","No") -> No | N2: 2012-09-04 | O2: 58 | P2: 635 | Q2: 88 | R2: 546 | S2: 172 | T2: 88 | U2: 88 | V2: =SUM(P2:U2) -> 1617 | W2: 3 | X2: 8 | Y2: 10 | Z2: 4 | AA2: 7 | AB2: 0 | AC2: 0 | AD2: 0 | AE2: 0 | AF2: 0 | AG2: =SUM(AB2:AF2) -> 0 | AH2: 0 | AI2: 1 | AK2: Income_Label | AN2: Data Quality Summary
A3: 2174 | B3: 1954 | C3: =2026-B3 -> 72 | D3: {=_xlfn.IFS(C3<36,"Young",C3<56,"Middle-aged",C3>=56,"Senior")} -> Senior | E3: Graduation | F3: Single | G3: 46344 | H3: =IF(G3=0,MEDIAN(Income),G3) -> 46344 | I3: {=_xlfn.IFS(H3<PERCENTILE(Income_Clean,0.33),"Low",H3<PERCENTILE(Income_Clean,0.67),"Medium",H3>PERCENTILE(Income_Clean,0.67),"High")} -> Medium | J3: =_xlfn.XLOOKUP(I3,$AK$3:$AK$5,$AL$3:$AL$5) -> Average Income | K3: 1 | L3: 1 | M3: =IF(K3+L3>0,"Yes","No") -> Yes | N3: 2014-03-08 | O3: 38 | P3: 11 | Q3: 1 | R3: 6 | S3: 2 | T3: 1 | U3: 6 | V3: =SUM(P3:U3) -> 27 | W3: 2 | X3: 1 | Y3: 1 | Z3: 2 | AA3: 5 | AB3: 0 | AC3: 0 | AD3: 0 | AE3: 0 | AF3: 0 | AG3: =SUM(AB3:AF3) -> 0 | AH3: 0 | AI3: 0 | AK3: Low | AL3: Below Average Income | AN3: Check | AO3: Result | AP3: Action
A4: 4141 | B4: 1965 | C4: =2026-B4 -> 61 | D4: {=_xlfn.IFS(C4<36,"Young",C4<56,"Middle-aged",C4>=56,"Senior")} -> Senior | E4: Graduation | F4: Together | G4: 71613 | H4: =IF(G4=0,MEDIAN(Income),G4) -> 71613 | I4: {=_xlfn.IFS(H4<PERCENTILE(Income_Clean,0.33),"Low",H4<PERCENTILE(Income_Clean,0.67),"Medium",H4>PERCENTILE(Income_Clean,0.67),"High")} -> High | J4: =_xlfn.XLOOKUP(I4,$AK$3:$AK$5,$AL$3:$AL$5) -> Above Average Income | K4: 0 | L4: 0 | M4: =IF(K4+L4>0,"Yes","No") -> No | N4: 2013-08-21 | O4: 26 | P4: 426 | Q4: 49 | R4: 127 | S4: 111 | T4: 21 | U4: 42 | V4: =SUM(P4:U4) -> 776 | W4: 1 | X4: 8 | Y4: 2 | Z4: 10 | AA4: 4 | AB4: 0 | AC4: 0 | AD4: 0 | AE4: 0 | AF4: 0 | AG4: =SUM(AB4:AF4) -> 0 | AH4: 0 | AI4: 0 | AK4: Medium | AL4: Average Income | AN4: Total Rows (before cleaning) | AO4: =COUNT('Raw Data'!A1:A2241) -> 2240
A5: 6182 | B5: 1984 | C5: =2026-B5 -> 42 | D5: {=_xlfn.IFS(C5<36,"Young",C5<56,"Middle-aged",C5>=56,"Senior")} -> Middle-aged | E5: Graduation | F5: Together | G5: 26646 | H5: =IF(G5=0,MEDIAN(Income),G5) -> 26646 | I5: {=_xlfn.IFS(H5<PERCENTILE(Income_Clean,0.33),"Low",H5<PERCENTILE(Income_Clean,0.67),"Medium",H5>PERCENTILE(Income_Clean,0.67),"High")} -> Low | J5: =_xlfn.XLOOKUP(I5,$AK$3:$AK$5,$AL$3:$AL$5) -> Below Average Income | K5: 1 | L5: 0 | M5: =IF(K5+L5>0,"Yes","No") -> Yes | N5: 2014-02-10 | O5: 26 | P5: 11 | Q5: 4 | R5: 20 | S5: 10 | T5: 3 | U5: 5 | V5: =SUM(P5:U5) -> 53 | W5: 2 | X5: 2 | Y5: 0 | Z5: 4 | AA5: 6 | AB5: 0 | AC5: 0 | AD5: 0 | AE5: 0 | AF5: 0 | AG5: =SUM(AB5:AF5) -> 0 | AH5: 0 | AI5: 0 | AK5: High | AL5: Above Average Income | AN5: Duplicate Rows | AO5: 0 | AP5: None needed
A6: 5324 | B6: 1981 | C6: =2026-B6 -> 45 | D6: {=_xlfn.IFS(C6<36,"Young",C6<56,"Middle-aged",C6>=56,"Senior")} -> Middle-aged | E6: PhD | F6: Married | G6: 58293 | H6: =IF(G6=0,MEDIAN(Income),G6) -> 58293 | I6: {=_xlfn.IFS(H6<PERCENTILE(Income_Clean,0.33),"Low",H6<PERCENTILE(Income_Clean,0.67),"Medium",H6>PERCENTILE(Income_Clean,0.67),"High")} -> Medium | J6: =_xlfn.XLOOKUP(I6,$AK$3:$AK$5,$AL$3:$AL$5) -> Average Income | K6: 1 | L6: 0 | M6: =IF(K6+L6>0,"Yes","No") -> Yes | N6: 2014-01-19 | O6: 94 | P6: 173 | Q6: 43 | R6: 118 | S6: 46 | T6: 27 | U6: 15 | V6: =SUM(P6:U6) -> 422 | W6: 5 | X6: 5 | Y6: 3 | Z6: 6 | AA6: 5 | AB6: 0 | AC6: 0 | AD6: 0 | AE6: 0 | AF6: 0 | AG6: =SUM(AB6:AF6) -> 0 | AH6: 0 | AI6: 0 | AN6: Missing Income values | AO6: =COUNTBLANK('Raw Data'!E1:E2241) -> 24 | AP6: Filled with median
A7: 7446 | B7: 1967 | C7: =2026-B7 -> 59 | D7: {=_xlfn.IFS(C7<36,"Young",C7<56,"Middle-aged",C7>=56,"Senior")} -> Senior | E7: Master | F7: Together | G7: 62513 | H7: =IF(G7=0,MEDIAN(Income),G7) -> 62513 | I7: {=_xlfn.IFS(H7<PERCENTILE(Income_Clean,0.33),"Low",H7<PERCENTILE(Income_Clean,0.67),"Medium",H7>PERCENTILE(Income_Clean,0.67),"High")} -> Medium | J7: =_xlfn.XLOOKUP(I7,$AK$3:$AK$5,$AL$3:$AL$5) -> Average Income | K7: 0 | L7: 1 | M7: =IF(K7+L7>0,"Yes","No") -> Yes | N7: 2013-09-09 | O7: 16 | P7: 520 | Q7: 42 | R7: 98 | S7: 0 | T7: 42 | U7: 14 | V7: =SUM(P7:U7) -> 716 | W7: 2 | X7: 6 | Y7: 4 | Z7: 10 | AA7: 6 | AB7: 0 | AC7: 0 | AD7: 0 | AE7: 0 | AF7: 0 | AG7: =SUM(AB7:AF7) -> 0 | AH7: 0 | AI7: 0 | AN7: Age outliers removed | AO7: 3 | AP7: Rows deleted
A8: 965 | B8: 1971 | C8: =2026-B8 -> 55 | D8: {=_xlfn.IFS(C8<36,"Young",C8<56,"Middle-aged",C8>=56,"Senior")} -> Middle-aged | E8: Graduation | F8: Divorced | G8: 55635 | H8: =IF(G8=0,MEDIAN(Income),G8) -> 55635 | I8: {=_xlfn.IFS(H8<PERCENTILE(Income_Clean,0.33),"Low",H8<PERCENTILE(Income_Clean,0.67),"Medium",H8>PERCENTILE(Income_Clean,0.67),"High")} -> Medium | J8: =_xlfn.XLOOKUP(I8,$AK$3:$AK$5,$AL$3:$AL$5) -> Average Income | K8: 0 | L8: 1 | M8: =IF(K8+L8>0,"Yes","No") -> Yes | N8: 2012-11-13 | O8: 34 | P8: 235 | Q8: 65 | R8: 164 | S8: 50 | T8: 49 | U8: 27 | V8: =SUM(P8:U8) -> 590 | W8: 4 | X8: 7 | Y8: 3 | Z8: 7 | AA8: 6 | AB8: 0 | AC8: 0 | AD8: 0 | AE8: 0 | AF8: 0 | AG8: =SUM(AB8:AF8) -> 0 | AH8: 0 | AI8: 0 | AN8: Income outliers removed | AO8: 1 | AP8: Rows deleted
A9: 6177 | B9: 1985 | C9: =2026-B9 -> 41 | D9: {=_xlfn.IFS(C9<36,"Young",C9<56,"Middle-aged",C9>=56,"Senior")} -> Middle-aged | E9: PhD | F9: Married | G9: 33454 | H9: =IF(G9=0,MEDIAN(Income),G9) -> 33454 | I9: {=_xlfn.IFS(H9<PERCENTILE(Income_Clean,0.33),"Low",H9<PERCENTILE(Income_Clean,0.67),"Medium",H9>PERCENTILE(Income_Clean,0.67),"High")} -> Low | J9: =_xlfn.XLOOKUP(I9,$AK$3:$AK$5,$AL$3:$AL$5) -> Below Average Income | K9: 1 | L9: 0 | M9: =IF(K9+L9>0,"Yes","No") -> Yes | N9: 2013-05-08 | O9: 32 | P9: 76 | Q9: 10 | R9: 56 | S9: 3 | T9: 1 | U9: 23 | V9: =SUM(P9:U9) -> 169 | W9: 2 | X9: 4 | Y9: 0 | Z9: 4 | AA9: 8 | AB9: 0 | AC9: 0 | AD9: 0 | AE9: 0 | AF9: 0 | AG9: =SUM(AB9:AF9) -> 0 | AH9: 0 | AI9: 0 | AN9: Marital_Status cleaned | AO9: 7 values | AP9: Recategorized
A10: 4855 | B10: 1974 | C10: =2026-B10 -> 52 | D10: {=_xlfn.IFS(C10<36,"Young",C10<56,"Middle-aged",C10>=56,"Senior")} -> Middle-aged | E10: PhD | F10: Together | G10: 30351 | H10: =IF(G10=0,MEDIAN(Income),G10) -> 30351 | I10: {=_xlfn.IFS(H10<PERCENTILE(Income_Clean,0.33),"Low",H10<PERCENTILE(Income_Clean,0.67),"Medium",H10>PERCENTILE(Income_Clean,0.67),"High")} -> Low | J10: =_xlfn.XLOOKUP(I10,$AK$3:$AK$5,$AL$3:$AL$5) -> Below Average Income | K10: 1 | L10: 0 | M10: =IF(K10+L10>0,"Yes","No") -> Yes | N10: 2013-06-06 | O10: 19 | P10: 14 | Q10: 0 | R10: 24 | S10: 3 | T10: 3 | U10: 2 | V10: =SUM(P10:U10) -> 46 | W10: 1 | X10: 3 | Y10: 0 | Z10: 2 | AA10: 9 | AB10: 0 | AC10: 0 | AD10: 0 | AE10: 0 | AF10: 0 | AG10: =SUM(AB10:AF10) -> 0 | AH10: 0 | AI10: 1 | AN10: Final Rows | AO10: =COUNT(A1:A2237) -> 2236 | AP10: Ready for analysis
A11: 5899 | B11: 1950 | C11: =2026-B11 -> 76 | D11: {=_xlfn.IFS(C11<36,"Young",C11<56,"Middle-aged",C11>=56,"Senior")} -> Senior | E11: PhD | F11: Together | G11: 5648 | H11: =IF(G11=0,MEDIAN(Income),G11) -> 5648 | I11: {=_xlfn.IFS(H11<PERCENTILE(Income_Clean,0.33),"Low",H11<PERCENTILE(Income_Clean,0.67),"Medium",H11>PERCENTILE(Income_Clean,0.67),"High")} -> Low | J11: =_xlfn.XLOOKUP(I11,$AK$3:$AK$5,$AL$3:$AL$5) -> Below Average Income | K11: 1 | L11: 1 | M11: =IF(K11+L11>0,"Yes","No") -> Yes | N11: 2014-03-13 | O11: 68 | P11: 28 | Q11: 0 | R11: 6 | S11: 1 | T11: 1 | U11: 13 | V11: =SUM(P11:U11) -> 49 | W11: 1 | X11: 1 | Y11: 0 | Z11: 0 | AA11: 20 | AB11: 1 | AC11: 0 | AD11: 0 | AE11: 0 | AF11: 0 | AG11: =SUM(AB11:AF11) -> 1 | AH11: 0 | AI11: 0
A12: 1994 | B12: 1983 | C12: =2026-B12 -> 43 | D12: {=_xlfn.IFS(C12<36,"Young",C12<56,"Middle-aged",C12>=56,"Senior")} -> Middle-aged | E12: Graduation | F12: Married | H12: =IF(G12=0,MEDIAN(Income),G12) -> 51371 | I12: {=_xlfn.IFS(H12<PERCENTILE(Income_Clean,0.33),"Low",H12<PERCENTILE(Income_Clean,0.67),"Medium",H12>PERCENTILE(Income_Clean,0.67),"High")} -> Medium | J12: =_xlfn.XLOOKUP(I12,$AK$3:$AK$5,$AL$3:$AL$5) -> Average Income | K12: 1 | L12: 0 | M12: =IF(K12+L12>0,"Yes","No") -> Yes | N12: 2013-11-15 | O12: 11 | P12: 5 | Q12: 5 | R12: 6 | S12: 0 | T12: 2 | U12: 1 | V12: =SUM(P12:U12) -> 19 | W12: 1 | X12: 1 | Y12: 0 | Z12: 2 | AA12: 7 | AB12: 0 | AC12: 0 | AD12: 0 | AE12: 0 | AF12: 0 | AG12: =SUM(AB12:AF12) -> 0 | AH12: 0 | AI12: 0
A13: 387 | B13: 1976 | C13: =2026-B13 -> 50 | D13: {=_xlfn.IFS(C13<36,"Young",C13<56,"Middle-aged",C13>=56,"Senior")} -> Middle-aged | E13: Basic | F13: Married | G13: 7500 | H13: =IF(G13=0,MEDIAN(Income),G13) -> 7500 | I13: {=_xlfn.IFS(H13<PERCENTILE(Income_Clean,0.33),"Low",H13<PERCENTILE(Income_Clean,0.67),"Medium",H13>PERCENTILE(Income_Clean,0.67),"High")} -> Low | J13: =_xlfn.XLOOKUP(I13,$AK$3:$AK$5,$AL$3:$AL$5) -> Below Average Income | K13: 0 | L13: 0 | M13: =IF(K13+L13>0,"Yes","No") -> No | N13: 2012-11-13 | O13: 59 | P13: 6 | Q13: 16 | R13: 11 | S13: 11 | T13: 1 | U13: 16 | V13: =SUM(P13:U13) -> 61 | W13: 1 | X13: 2 | Y13: 0 | Z13: 3 | AA13: 8 | AB13: 0 | AC13: 0 | AD13: 0 | AE13: 0 | AF13: 0 | AG13: =SUM(AB13:AF13) -> 0 | AH13: 0 | AI13: 0
A14: 2125 | B14: 1959 | C14: =2026-B14 -> 67 | D14: {=_xlfn.IFS(C14<36,"Young",C14<56,"Middle-aged",C14>=56,"Senior")} -> Senior | E14: Graduation | F14: Divorced | G14: 63033 | H14: =IF(G14=0,MEDIAN(Income),G14) -> 63033 | I14: {=_xlfn.IFS(H14<PERCENTILE(Income_Clean,0.33),"Low",H14<PERCENTILE(Income_Clean,0.67),"Medium",H14>PERCENTILE(Income_Clean,0.67),"High")} -> High | J14: =_xlfn.XLOOKUP(I14,$AK$3:$AK$5,$AL$3:$AL$5) -> Above Average Income | K14: 0 | L14: 0 | M14: =IF(K14+L14>0,"Yes","No") -> No | N14: 2013-11-15 | O14: 82 | P14: 194 | Q14: 61 | R14: 480 | S14: 225 | T14: 112 | U14: 30 | V14: =SUM(P14:U14) -> 1102 | W14: 1 | X14: 3 | Y14: 4 | Z14: 8 | AA14: 2 | AB14: 0 | AC14: 0 | AD14: 0 | AE14: 0 | AF14: 0 | AG14: =SUM(AB14:AF14) -> 0 | AH14: 0 | AI14: 0
A15: 8180 | B15: 1952 | C15: =2026-B15 -> 74 | D15: {=_xlfn.IFS(C15<36,"Young",C15<56,"Middle-aged",C15>=56,"Senior")} -> Senior | E15: Master | F15: Divorced | G15: 59354 | H15: =IF(G15=0,MEDIAN(Income),G15) -> 59354 | I15: {=_xlfn.IFS(H15<PERCENTILE(Income_Clean,0.33),"Low",H15<PERCENTILE(Income_Clean,0.67),"Medium",H15>PERCENTILE(Income_Clean,0.67),"High")} -> Medium | J15: =_xlfn.XLOOKUP(I15,$AK$3:$AK$5,$AL$3:$AL$5) -> Average Income | K15: 1 | L15: 1 | M15: =IF(K15+L15>0,"Yes","No") -> Yes | N15: 2013-11-15 | O15: 53 | P15: 233 | Q15: 2 | R15: 53 | S15: 3 | T15: 5 | U15: 14 | V15: =SUM(P15:U15) -> 310 | W15: 3 | X15: 6 | Y15: 1 | Z15: 5 | AA15: 6 | AB15: 0 | AC15: 0 | AD15: 0 | AE15: 0 | AF15: 0 | AG15: =SUM(AB15:AF15) -> 0 | AH15: 0 | AI15: 0
A16: 2569 | B16: 1987 | C16: =2026-B16 -> 39 | D16: {=_xlfn.IFS(C16<36,"Young",C16<56,"Middle-aged",C16>=56,"Senior")} -> Middle-aged | E16: Graduation | F16: Married | G16: 17323 | H16: =IF(G16=0,MEDIAN(Income),G16) -> 17323 | I16: {=_xlfn.IFS(H16<PERCENTILE(Income_Clean,0.33),"Low",H16<PERCENTILE(Income_Clean,0.67),"Medium",H16>PERCENTILE(Income_Clean,0.67),"High")} -> Low | J16: =_xlfn.XLOOKUP(I16,$AK$3:$AK$5,$AL$3:$AL$5) -> Below Average Income | K16: 0 | L16: 0 | M16: =IF(K16+L16>0,"Yes","No") -> No | N16: 2012-10-10 | O16: 38 | P16: 3 | Q16: 14 | R16: 17 | S16: 6 | T16: 1 | U16: 5 | V16: =SUM(P16:U16) -> 46 | W16: 1 | X16: 1 | Y16: 0 | Z16: 3 | AA16: 8 | AB16: 0 | AC16: 0 | AD16: 0 | AE16: 0 | AF16: 0 | AG16: =SUM(AB16:AF16) -> 0 | AH16: 0 | AI16: 0
A17: 2114 | B17: 1946 | C17: =2026-B17 -> 80 | D17: {=_xlfn.IFS(C17<36,"Young",C17<56,"Middle-aged",C17>=56,"Senior")} -> Senior | E17: PhD | F17: Single | G17: 82800 | H17: =IF(G17=0,MEDIAN(Income),G17) -> 82800 | I17: {=_xlfn.IFS(H17<PERCENTILE(Income_Clean,0.33),"Low",H17<PERCENTILE(Income_Clean,0.67),"Medium",H17>PERCENTILE(Income_Clean,0.67),"High")} -> High | J17: =_xlfn.XLOOKUP(I17,$AK$3:$AK$5,$AL$3:$AL$5) -> Above Average Income | K17: 0 | L17: 0 | M17: =IF(K17+L17>0,"Yes","No") -> No | N17: 2012-11-24 | O17: 23 | P17: 1006 | Q17: 22 | R17: 115 | S17: 59 | T17: 68 | U17: 45 | V17: =SUM(P17:U17) -> 1315 | W17: 1 | X17: 7 | Y17: 6 | Z17: 12 | AA17: 3 | AB17: 0 | AC17: 0 | AD17: 1 | AE17: 1 | AF17: 0 | AG17: =SUM(AB17:AF17) -> 2 | AH17: 0 | AI17: 1
A18: 9736 | B18: 1980 | C18: =2026-B18 -> 46 | D18: {=_xlfn.IFS(C18<36,"Young",C18<56,"Middle-aged",C18>=56,"Senior")} -> Middle-aged | E18: Graduation | F18: Married | G18: 41850 | H18: =IF(G18=0,MEDIAN(Income),G18) -> 41850 | I18: {=_xlfn.IFS(H18<PERCENTILE(Income_Clean,0.33),"Low",H18<PERCENTILE(Income_Clean,0.67),"Medium",H18>PERCENTILE(Income_Clean,0.67),"High")} -> Medium | J18: =_xlfn.XLOOKUP(I18,$AK$3:$AK$5,$AL$3:$AL$5) -> Average Income | K18: 1 | L18: 1 | M18: =IF(K18+L18>0,"Yes","No") -> Yes | N18: 2012-12-24 | O18: 51 | P18: 53 | Q18: 5 | R18: 19 | S18: 2 | T18: 13 | U18: 4 | V18: =SUM(P18:U18) -> 96 | W18: 3 | X18: 3 | Y18: 0 | Z18: 3 | AA18: 8 | AB18: 0 | AC18: 0 | AD18: 0 | AE18: 0 | AF18: 0 | AG18: =SUM(AB18:AF18) -> 0 | AH18: 0 | AI18: 0
A19: 4939 | B19: 1946 | C19: =2026-B19 -> 80 | D19: {=_xlfn.IFS(C19<36,"Young",C19<56,"Middle-aged",C19>=56,"Senior")} -> Senior | E19: Graduation | F19: Together | G19: 37760 | H19: =IF(G19=0,MEDIAN(Income),G19) -> 37760 | I19: {=_xlfn.IFS(H19<PERCENTILE(Income_Clean,0.33),"Low",H19<PERCENTILE(Income_Clean,0.67),"Medium",H19>PERCENTILE(Income_Clean,0.67),"High")} -> Low | J19: =_xlfn.XLOOKUP(I19,$AK$3:$AK$5,$AL$3:$AL$5) -> Below Average Income | K19: 0 | L19: 0 | M19: =IF(K19+L19>0,"Yes","No") -> No | N19: 2012-08-31 | O19: 20 | P19: 84 | Q19: 5 | R19: 38 | S19: 150 | T19: 12 | U19: 28 | V19: =SUM(P19:U19) -> 317 | W19: 2 | X19: 4 | Y19: 1 | Z19: 6 | AA19: 7 | AB19: 0 | AC19: 0 | AD19: 0 | AE19: 0 | AF19: 0 | AG19: =SUM(AB19:AF19) -> 0 | AH19: 0 | AI19: 0
A20: 6565 | B20: 1949 | C20: =2026-B20 -> 77 | D20: {=_xlfn.IFS(C20<36,"Young",C20<56,"Middle-aged",C20>=56,"Senior")} -> Senior | E20: Master | F20: Married | G20: 76995 | H20: =IF(G20=0,MEDIAN(Income),G20) -> 76995 | I20: {=_xlfn.IFS(H20<PERCENTILE(Income_Clean,0.33),"Low",H20<PERCENTILE(Income_Clean,0.67),"Medium",H20>PERCENTILE(Income_Clean,0.67),"High")} -> High | J20: =_xlfn.XLOOKUP(I20,$AK$3:$AK$5,$AL$3:$AL$5) -> Above Average Income | K20: 0 | L20: 1 | M20: =IF(K20+L20>0,"Yes","No") -> Yes | N20: 2013-03-28 | O20: 91 | P20: 1012 | Q20: 80 | R20: 498 | S20: 0 | T20: 16 | U20: 176 | V20: =SUM(P20:U20) -> 1782 | W20: 2 | X20: 11 | Y20: 4 | Z20: 9 | AA20: 5 | AB20: 0 | AC20: 0 | AD20: 0 | AE20: 1 | AF20: 0 | AG20: =SUM(AB20:AF20) -> 1 | AH20: 0 | AI20: 0
A21: 2278 | B21: 1985 | C21: =2026-B21 -> 41 | D21: {=_xlfn.IFS(C21<36,"Young",C21<56,"Middle-aged",C21>=56,"Senior")} -> Middle-aged | E21: 2n Cycle | F21: Single | G21: 33812 | H21: =IF(G21=0,MEDIAN(Income),G21) -> 33812 | I21: {=_xlfn.IFS(H21<PERCENTILE(Income_Clean,0.33),"Low",H21<PERCENTILE(Income_Clean,0.67),"Medium",H21>PERCENTILE(Income_Clean,0.67),"High")} -> Low | J21: =_xlfn.XLOOKUP(I21,$AK$3:$AK$5,$AL$3:$AL$5) -> Below Average Income | K21: 1 | L21: 0 | M21: =IF(K21+L21>0,"Yes","No") -> Yes | N21: 2012-11-03 | O21: 86 | P21: 4 | Q21: 17 | R21: 19 | S21: 30 | T21: 24 | U21: 39 | V21: =SUM(P21:U21) -> 133 | W21: 2 | X21: 2 | Y21: 1 | Z21: 3 | AA21: 6 | AB21: 0 | AC21: 0 | AD21: 0 | AE21: 0 | AF21: 0 | AG21: =SUM(AB21:AF21) -> 0 | AH21: 0 | AI21: 0
A22: 9360 | B22: 1982 | C22: =2026-B22 -> 44 | D22: {=_xlfn.IFS(C22<36,"Young",C22<56,"Middle-aged",C22>=56,"Senior")} -> Middle-aged | E22: Graduation | F22: Married | G22: 37040 | H22: =IF(G22=0,MEDIAN(Income),G22) -> 37040 | I22: {=_xlfn.IFS(H22<PERCENTILE(Income_Clean,0.33),"Low",H22<PERCENTILE(Income_Clean,0.67),"Medium",H22>PERCENTILE(Income_Clean,0.67),"High")} -> Low | J22: =_xlfn.XLOOKUP(I22,$AK$3:$AK$5,$AL$3:$AL$5) -> Below Average Income | K22: 0 | L22: 0 | M22: =IF(K22+L22>0,"Yes","No") -> No | N22: 2012-08-08 | O22: 41 | P22: 86 | Q22: 2 | R22: 73 | S22: 69 | T22: 38 | U22: 48 | V22: =SUM(P22:U22) -> 316 | W22: 1 | X22: 4 | Y22: 2 | Z22: 5 | AA22: 8 | AB22: 0 | AC22: 0 | AD22: 0 | AE22: 0 | AF22: 0 | AG22: =SUM(AB22:AF22) -> 0 | AH22: 0 | AI22: 0
A23: 5376 | B23: 1979 | C23: =2026-B23 -> 47 | D23: {=_xlfn.IFS(C23<36,"Young",C23<56,"Middle-aged",C23>=56,"Senior")} -> Middle-aged | E23: Graduation | F23: Married | G23: 2447 | H23: =IF(G23=0,MEDIAN(Income),G23) -> 2447 | I23: {=_xlfn.IFS(H23<PERCENTILE(Income_Clean,0.33),"Low",H23<PERCENTILE(Income_Clean,0.67),"Medium",H23>PERCENTILE(Income_Clean,0.67),"High")} -> Low | J23: =_xlfn.XLOOKUP(I23,$AK$3:$AK$5,$AL$3:$AL$5) -> Below Average Income | K23: 1 | L23: 0 | M23: =IF(K23+L23>0,"Yes","No") -> Yes | N23: 2013-01-06 | O23: 42 | P23: 1 | Q23: 1 | R23: 1725 | S23: 1 | T23: 1 | U23: 1 | V23: =SUM(P23:U23) -> 1730 | W23: 15 | X23: 0 | Y23: 28 | Z23: 0 | AA23: 1 | AB23: 0 | AC23: 0 | AD23: 0 | AE23: 0 | AF23: 0 | AG23: =SUM(AB23:AF23) -> 0 | AH23: 0 | AI23: 0
A24: 1993 | B24: 1949 | C24: =2026-B24 -> 77 | D24: {=_xlfn.IFS(C24<36,"Young",C24<56,"Middle-aged",C24>=56,"Senior")} -> Senior | E24: PhD | F24: Married | G24: 58607 | H24: =IF(G24=0,MEDIAN(Income),G24) -> 58607 | I24: {=_xlfn.IFS(H24<PERCENTILE(Income_Clean,0.33),"Low",H24<PERCENTILE(Income_Clean,0.67),"Medium",H24>PERCENTILE(Income_Clean,0.67),"High")} -> Medium | J24: =_xlfn.XLOOKUP(I24,$AK$3:$AK$5,$AL$3:$AL$5) -> Average Income | K24: 0 | L24: 1 | M24: =IF(K24+L24>0,"Yes","No") -> Yes | N24: 2012-12-23 | O24: 63 | P24: 867 | Q24: 0 | R24: 86 | S24: 0 | T24: 0 | U24: 19 | V24: =SUM(P24:U24) -> 972 | W24: 3 | X24: 2 | Y24: 3 | Z24: 9 | AA24: 8 | AB24: 0 | AC24: 1 | AD24: 0 | AE24: 0 | AF24: 0 | AG24: =SUM(AB24:AF24) -> 1 | AH24: 0 | AI24: 0
... A28: 2404 | B28: 1976 | C28: =2026-B28 -> 50 | D28: {=_xlfn.IFS(C28<36,"Young",C28<56,"Middle-aged",C28>=56,"Senior")} -> Middle-aged | E28: Graduation | F28: Married | G28: 53359 | H28: =IF(G28=0,MEDIAN(Income),G28) -> 53359 | I28: {=_xlfn.IFS(H28<PERCENTILE(Income_Clean,0.33),"Low",H28<PERCENTILE(Income_Clean,0.67),"Medium",H28>PERCENTILE(Income_Clean,0.67),"High")} -> Medium | J28: =_xlfn.XLOOKUP(I28,$AK$3:$AK$5,$AL$3:$AL$5) -> Average Income | K28: 1 | L28: 1 | M28: =IF(K28+L28>0,"Yes","No") -> Yes | N28: 2013-05-27 | O28: 4 | P28: 173 | Q28: 4 | R28: 30 | S28: 3 | T28: 6 | U28: 41 | V28: =SUM(P28:U28) -> 257 | W28: 4 | X28: 5 | Y28: 1 | Z28: 4 | AA28: 7 | AB28: 0 | AC28: 0 | AD28: 0 | AE28: 0 | AF28: 0 | AG28: =SUM(AB28:AF28) -> 0 | AH28: 0 | AI28: 0
A29: 5255 | B29: 1986 | C29: =2026-B29 -> 40 | D29: {=_xlfn.IFS(C29<36,"Young",C29<56,"Middle-aged",C29>=56,"Senior")} -> Middle-aged | E29: Graduation | F29: Single | H29: =IF(G29=0,MEDIAN(Income),G29) -> 51371 | I29: {=_xlfn.IFS(H29<PERCENTILE(Income_Clean,0.33),"Low",H29<PERCENTILE(Income_Clean,0.67),"Medium",H29>PERCENTILE(Income_Clean,0.67),"High")} -> Medium | J29: =_xlfn.XLOOKUP(I29,$AK$3:$AK$5,$AL$3:$AL$5) -> Average Income | K29: 1 | L29: 0 | M29: =IF(K29+L29>0,"Yes","No") -> Yes | N29: 2013-02-20 | O29: 19 | P29: 5 | Q29: 1 | R29: 3 | S29: 3 | T29: 263 | U29: 362 | V29: =SUM(P29:U29) -> 637 | W29: 0 | X29: 27 | Y29: 0 | Z29: 0 | AA29: 1 | AB29: 0 | AC29: 0 | AD29: 0 | AE29: 0 | AF29: 0 | AG29: =SUM(AB29:AF29) -> 0 | AH29: 0 | AI29: 0
A30: 9422 | B30: 1989 | C30: =2026-B30 -> 37 | D30: {=_xlfn.IFS(C30<36,"Young",C30<56,"Middle-aged",C30>=56,"Senior")} -> Middle-aged | E30: Graduation | F30: Married | G30: 38360 | H30: =IF(G30=0,MEDIAN(Income),G30) -> 38360 | I30: {=_xlfn.IFS(H30<PERCENTILE(Income_Clean,0.33),"Low",H30<PERCENTILE(Income_Clean,0.67),"Medium",H30>PERCENTILE(Income_Clean,0.67),"High")} -> Low | J30: =_xlfn.XLOOKUP(I30,$AK$3:$AK$5,$AL$3:$AL$5) -> Below Average Income | K30: 1 | L30: 0 | M30: =IF(K30+L30>0,"Yes","No") -> Yes | N30: 2013-05-31 | O30: 26 | P30: 36 | Q30: 2 | R30: 42 | S30: 20 | T30: 21 | U30: 10 | V30: =SUM(P30:U30) -> 131 | W30: 2 | X30: 2 | Y30: 1 | Z30: 4 | AA30: 3 | AB30: 0 | AC30: 0 | AD30: 0 | AE30: 0 | AF30: 0 | AG30: =SUM(AB30:AF30) -> 0 | AH30: 0 | AI30: 0
A31: 1966 | B31: 1965 | C31: =2026-B31 -> 61 | D31: {=_xlfn.IFS(C31<36,"Young",C31<56,"Middle-aged",C31>=56,"Senior")} -> Senior | E31: PhD | F31: Married | G31: 84618 | H31: =IF(G31=0,MEDIAN(Income),G31) -> 84618 | I31: {=_xlfn.IFS(H31<PERCENTILE(Income_Clean,0.33),"Low",H31<PERCENTILE(Income_Clean,0.67),"Medium",H31>PERCENTILE(Income_Clean,0.67),"High")} -> High | J31: =_xlfn.XLOOKUP(I31,$AK$3:$AK$5,$AL$3:$AL$5) -> Above Average Income | K31: 0 | L31: 0 | M31: =IF(K31+L31>0,"Yes","No") -> No | N31: 2013-11-22 | O31: 96 | P31: 684 | Q31: 100 | R31: 801 | S31: 21 | T31: 66 | U31: 0 | V31: =SUM(P31:U31) -> 1672 | W31: 1 | X31: 6 | Y31: 9 | Z31: 10 | AA31: 2 | AB31: 0 | AC31: 0 | AD31: 1 | AE31: 0 | AF31: 0 | AG31: =SUM(AB31:AF31) -> 1 | AH31: 0 | AI31: 0
A32: 6864 | B32: 1989 | C32: =2026-B32 -> 37 | D32: {=_xlfn.IFS(C32<36,"Young",C32<56,"Middle-aged",C32>=56,"Senior")} -> Middle-aged | E32: Master | F32: Divorced | G32: 10979 | H32: =IF(G32=0,MEDIAN(Income),G32) -> 10979 | I32: {=_xlfn.IFS(H32<PERCENTILE(Income_Clean,0.33),"Low",H32<PERCENTILE(Income_Clean,0.67),"Medium",H32>PERCENTILE(Income_Clean,0.67),"High")} -> Low | J32: =_xlfn.XLOOKUP(I32,$AK$3:$AK$5,$AL$3:$AL$5) -> Below Average Income | K32: 0 | L32: 0 | M32: =IF(K32+L32>0,"Yes","No") -> No | N32: 2014-05-22 | O32: 34 | P32: 8 | Q32: 4 | R32: 10 | S32: 2 | T32: 2 | U32: 4 | V32: =SUM(P32:U32) -> 30 | W32: 2 | X32: 3 | Y32: 0 | Z32: 3 | AA32: 5 | AB32: 0 | AC32: 0 | AD32: 0 | AE32: 0 | AF32: 0 | AG32: =SUM(AB32:AF32) -> 0 | AH32: 0 | AI32: 0
A33: 3033 | B33: 1963 | C33: =2026-B33 -> 63 | D33: {=_xlfn.IFS(C33<36,"Young",C33<56,"Middle-aged",C33>=56,"Senior")} -> Senior | E33: Master | F33: Together | G33: 38620 | H33: =IF(G33=0,MEDIAN(Income),G33) -> 38620 | I33: {=_xlfn.IFS(H33<PERCENTILE(Income_Clean,0.33),"Low",H33<PERCENTILE(Income_Clean,0.67),"Medium",H33>PERCENTILE(Income_Clean,0.67),"High")} -> Low | J33: =_xlfn.XLOOKUP(I33,$AK$3:$AK$5,$AL$3:$AL$5) -> Below Average Income | K33: 0 | L33: 0 | M33: =IF(K33+L33>0,"Yes","No") -> No | N33: 2013-05-11 | O33: 56 | P33: 112 | Q33: 17 | R33: 44 | S33: 34 | T33: 22 | U33: 89 | V33: =SUM(P33:U33) -> 318 | W33: 1 | X33: 2 | Y33: 5 | Z33: 3 | AA33: 3 | AB33: 0 | AC33: 0 | AD33: 0 | AE33: 0 | AF33: 0 | AG33: =SUM(AB33:AF33) -> 0 | AH33: 0 | AI33: 0
A34: 5710 | B34: 1970 | C34: =2026-B34 -> 56 | D34: {=_xlfn.IFS(C34<36,"Young",C34<56,"Middle-aged",C34>=56,"Senior")} -> Senior | E34: Graduation | F34: Together | G34: 40548 | H34: =IF(G34=0,MEDIAN(Income),G34) -> 40548 | I34: {=_xlfn.IFS(H34<PERCENTILE(Income_Clean,0.33),"Low",H34<PERCENTILE(Income_Clean,0.67),"Medium",H34>PERCENTILE(Income_Clean,0.67),"High")} -> Medium | J34: =_xlfn.XLOOKUP(I34,$AK$3:$AK$5,$AL$3:$AL$5) -> Average Income | K34: 0 | L34: 1 | M34: =IF(K34+L34>0,"Yes","No") -> Yes | N34: 2012-10-10 | O34: 31 | P34: 110 | Q34: 0 | R34: 5 | S34: 2 | T34: 0 | U34: 3 | V34: =SUM(P34:U34) -> 120 | W34: 2 | X34: 2 | Y34: 1 | Z34: 4 | AA34: 5 | AB34: 0 | AC34: 1 | AD34: 0 | AE34: 0 | AF34: 0 | AG34: =SUM(AB34:AF34) -> 1 | AH34: 0 | AI34: 0
A35: 7373 | B35: 1952 | C35: =2026-B35 -> 74 | D35: {=_xlfn.IFS(C35<36,"Young",C35<56,"Middle-aged",C35>=56,"Senior")} -> Senior | E35: PhD | F35: Divorced | G35: 46610 | H35: =IF(G35=0,MEDIAN(Income),G35) -> 46610 | I35: {=_xlfn.IFS(H35<PERCENTILE(Income_Clean,0.33),"Low",H35<PERCENTILE(Income_Clean,0.67),"Medium",H35>PERCENTILE(Income_Clean,0.67),"High")} -> Medium | J35: =_xlfn.XLOOKUP(I35,$AK$3:$AK$5,$AL$3:$AL$5) -> Average Income | K35: 0 | L35: 2 | M35: =IF(K35+L35>0,"Yes","No") -> Yes | N35: 2012-10-29 | O35: 8 | P35: 96 | Q35: 12 | R35: 96 | S35: 33 | T35: 22 | U35: 43 | V35: =SUM(P35:U35) -> 302 | W35: 6 | X35: 4 | Y35: 1 | Z35: 6 | AA35: 6 | AB35: 0 | AC35: 0 | AD35: 0 | AE35: 0 | AF35: 0 | AG35: =SUM(AB35:AF35) -> 0 | AH35: 0 | AI35: 1
A36: 8755 | B36: 1946 | C36: =2026-B36 -> 80 | D36: {=_xlfn.IFS(C36<36,"Young",C36<56,"Middle-aged",C36>=56,"Senior")} -> Senior | E36: Master | F36: Married | G36: 68657 | H36: =IF(G36=0,MEDIAN(Income),G36) -> 68657 | I36: {=_xlfn.IFS(H36<PERCENTILE(Income_Clean,0.33),"Low",H36<PERCENTILE(Income_Clean,0.67),"Medium",H36>PERCENTILE(Income_Clean,0.67),"High")} -> High | J36: =_xlfn.XLOOKUP(I36,$AK$3:$AK$5,$AL$3:$AL$5) -> Above Average Income | K36: 0 | L36: 0 | M36: =IF(K36+L36>0,"Yes","No") -> No | N36: 2013-02-20 | O36: 4 | P36: 482 | Q36: 34 | R36: 471 | S36: 119 | T36: 68 | U36: 22 | V36: =SUM(P36:U36) -> 1196 | W36: 1 | X36: 3 | Y36: 5 | Z36: 9 | AA36: 7 | AB36: 0 | AC36: 0 | AD36: 0 | AE36: 0 | AF36: 0 | AG36: =SUM(AB36:AF36) -> 0 | AH36: 0 | AI36: 0
A37: 10738 | B37: 1951 | C37: =2026-B37 -> 75 | D37: {=_xlfn.IFS(C37<36,"Young",C37<56,"Middle-aged",C37>=56,"Senior")} -> Senior | E37: Master | F37: Single | G37: 49389 | H37: =IF(G37=0,MEDIAN(Income),G37) -> 49389 | I37: {=_xlfn.IFS(H37<PERCENTILE(Income_Clean,0.33),"Low",H37<PERCENTILE(Income_Clean,0.67),"Medium",H37>PERCENTILE(Income_Clean,0.67),"High")} -> Medium | J37: =_xlfn.XLOOKUP(I37,$AK$3:$AK$5,$AL$3:$AL$5) -> Average Income | K37: 1 | L37: 1 | M37: =IF(K37+L37>0,"Yes","No") -> Yes | N37: 2013-08-29 | O37: 55 | P37: 40 | Q37: 0 | R37: 19 | S37: 2 | T37: 1 | U37: 3 | V37: =SUM(P37:U37) -> 65 | W37: 1 | X37: 2 | Y37: 0 | Z37: 3 | AA37: 7 | AB37: 0 | AC37: 0 | AD37: 0 | AE37: 0 | AF37: 0 | AG37: =SUM(AB37:AF37) -> 0 | AH37: 0 | AI37: 0
A38: 4339 | B38: 1970 | C38: =2026-B38 -> 56 | D38: {=_xlfn.IFS(C38<36,"Young",C38<56,"Middle-aged",C38>=56,"Senior")} -> Senior | E38: PhD | F38: Married | G38: 67353 | H38: =IF(G38=0,MEDIAN(Income),G38) -> 67353 | I38: {=_xlfn.IFS(H38<PERCENTILE(Income_Clean,0.33),"Low",H38<PERCENTILE(Income_Clean,0.67),"Medium",H38>PERCENTILE(Income_Clean,0.67),"High")} -> High | J38: =_xlfn.XLOOKUP(I38,$AK$3:$AK$5,$AL$3:$AL$5) -> Above Average Income | K38: 0 | L38: 1 | M38: =IF(K38+L38>0,"Yes","No") -> Yes | N38: 2013-12-31 | O38: 37 | P38: 702 | Q38: 17 | R38: 151 | S38: 0 | T38: 8 | U38: 35 | V38: =SUM(P38:U38) -> 913 | W38: 5 | X38: 5 | Y38: 6 | Z38: 12 | AA38: 2 | AB38: 0 | AC38: 0 | AD38: 0 | AE38: 0 | AF38: 0 | AG38: =SUM(AB38:AF38) -> 0 | AH38: 0 | AI38: 0
A39: 10755 | B39: 1976 | C39: =2026-B39 -> 50 | D39: {=_xlfn.IFS(C39<36,"Young",C39<56,"Middle-aged",C39>=56,"Senior")} -> Middle-aged | E39: 2n Cycle | F39: Married | G39: 23718 | H39: =IF(G39=0,MEDIAN(Income),G39) -> 23718 | I39: {=_xlfn.IFS(H39<PERCENTILE(Income_Clean,0.33),"Low",H39<PERCENTILE(Income_Clean,0.67),"Medium",H39>PERCENTILE(Income_Clean,0.67),"High")} -> Low | J39: =_xlfn.XLOOKUP(I39,$AK$3:$AK$5,$AL$3:$AL$5) -> Below Average Income | K39: 1 | L39: 0 | M39: =IF(K39+L39>0,"Yes","No") -> Yes | N39: 2013-09-02 | O39: 76 | P39: 6 | Q39: 3 | R39: 14 | S39: 15 | T39: 7 | U39: 36 | V39: =SUM(P39:U39) -> 81 | W39: 3 | X39: 3 | Y39: 1 | Z39: 2 | AA39: 7 | AB39: 0 | AC39: 0 | AD39: 0 | AE39: 0 | AF39: 0 | AG39: =SUM(AB39:AF39) -> 0 | AH39: 0 | AI39: 0
A40: 8595 | B40: 1973 | C40: =2026-B40 -> 53 | D40: {=_xlfn.IFS(C40<36,"Young",C40<56,"Middle-aged",C40>=56,"Senior")} -> Middle-aged | E40: Graduation | F40: Widow | G40: 42429 | H40: =IF(G40=0,MEDIAN(Income),G40) -> 42429 | I40: {=_xlfn.IFS(H40<PERCENTILE(Income_Clean,0.33),"Low",H40<PERCENTILE(Income_Clean,0.67),"Medium",H40>PERCENTILE(Income_Clean,0.67),"High")} -> Medium | J40: =_xlfn.XLOOKUP(I40,$AK$3:$AK$5,$AL$3:$AL$5) -> Average Income | K40: 0 | L40: 1 | M40: =IF(K40+L40>0,"Yes","No") -> Yes | N40: 2014-02-11 | O40: 99 | P40: 55 | Q40: 0 | R40: 6 | S40: 2 | T40: 0 | U40: 4 | V40: =SUM(P40:U40) -> 67 | W40: 2 | X40: 1 | Y40: 1 | Z40: 3 | AA40: 5 | AB40: 0 | AC40: 0 | AD40: 0 | AE40: 0 | AF40: 0 | AG40: =SUM(AB40:AF40) -> 0 | AH40: 0 | AI40: 0
A41: 2968 | B41: 1943 | C41: =2026-B41 -> 83 | D41: {=_xlfn.IFS(C41<36,"Young",C41<56,"Middle-aged",C41>=56,"Senior")} -> Senior | E41: PhD | F41: Divorced | G41: 48948 | H41: =IF(G41=0,MEDIAN(Income),G41) -> 48948 | I41: {=_xlfn.IFS(H41<PERCENTILE(Income_Clean,0.33),"Low",H41<PERCENTILE(Income_Clean,0.67),"Medium",H41>PERCENTILE(Income_Clean,0.67),"High")} -> Medium | J41: =_xlfn.XLOOKUP(I41,$AK$3:$AK$5,$AL$3:$AL$5) -> Average Income | K41: 0 | L41: 0 | M41: =IF(K41+L41>0,"Yes","No") -> No | N41: 2013-02-01 | O41: 53 | P41: 437 | Q41: 8 | R41: 206 | S41: 160 | T41: 49 | U41: 42 | V41: =SUM(P41:U41) -> 902 | W41: 2 | X41: 7 | Y41: 10 | Z41: 5 | AA41: 6 | AB41: 1 | AC41: 0 | AD41: 0 | AE41: 0 | AF41: 0 | AG41: =SUM(AB41:AF41) -> 1 | AH41: 0 | AI41: 1
... A44: 8430 | B44: 1957 | C44: =2026-B44 -> 69 | D44: {=_xlfn.IFS(C44<36,"Young",C44<56,"Middle-aged",C44>=56,"Senior")} -> Senior | E44: Graduation | F44: Together | G44: 21994 | H44: =IF(G44=0,MEDIAN(Income),G44) -> 21994 | I44: {=_xlfn.IFS(H44<PERCENTILE(Income_Clean,0.33),"Low",H44<PERCENTILE(Income_Clean,0.67),"Medium",H44>PERCENTILE(Income_Clean,0.67),"High")} -> Low | J44: =_xlfn.XLOOKUP(I44,$AK$3:$AK$5,$AL$3:$AL$5) -> Below Average Income | K44: 0 | L44: 1 | M44: =IF(K44+L44>0,"Yes","No") -> Yes | N44: 2012-12-24 | O44: 4 | P44: 9 | Q44: 0 | R44: 6 | S44: 3 | T44: 1 | U44: 3 | V44: =SUM(P44:U44) -> 22 | W44: 1 | X44: 0 | Y44: 0 | Z44: 3 | AA44: 5 | AB44: 0 | AC44: 0 | AD44: 0 | AE44: 0 | AF44: 0 | AG44: =SUM(AB44:AF44) -> 0 | AH44: 0 | AI44: 0
A45: 7281 | B45: 1959 | C45: =2026-B45 -> 67 | D45: {=_xlfn.IFS(C45<36,"Young",C45<56,"Middle-aged",C45>=56,"Senior")} -> Senior | E45: PhD | F45: Single | H45: =IF(G45=0,MEDIAN(Income),G45) -> 51371 | I45: {=_xlfn.IFS(H45<PERCENTILE(Income_Clean,0.33),"Low",H45<PERCENTILE(Income_Clean,0.67),"Medium",H45>PERCENTILE(Income_Clean,0.67),"High")} -> Medium | J45: =_xlfn.XLOOKUP(I45,$AK$3:$AK$5,$AL$3:$AL$5) -> Average Income | K45: 0 | L45: 0 | M45: =IF(K45+L45>0,"Yes","No") -> No | N45: 2013-11-05 | O45: 80 | P45: 81 | Q45: 11 | R45: 50 | S45: 3 | T45: 2 | U45: 39 | V45: =SUM(P45:U45) -> 186 | W45: 1 | X45: 1 | Y45: 3 | Z45: 4 | AA45: 2 | AB45: 0 | AC45: 0 | AD45: 0 | AE45: 0 | AF45: 0 | AG45: =SUM(AB45:AF45) -> 0 | AH45: 0 | AI45: 0
...

Sheet Typical Client
A1: Who is our typical client?
A3: Age_Group | B3: Count | C3: %
A4: Senior | B4: 1150 | C4: 0.51532569 | L4: The customer base is heavily concentrated in the Senior segment (56+), making this group critical for retention and campaign performance.
A5: Middle-aged | B5: 1043 | C5: 0.46470355
A6: Young | B6: 43 | C6: 0.019970756
A25: Education | B25: Count | C25: %
A26: Graduation | B26: 1126 | C26: 0.50357782 | L26: Over 50% of customers hold a university degree (Graduation level).
A27: PhD | B27: 485 | C27: 0.21690519
A28: Master | B28: 370 | C28: 0.16547406
A29: 2n Cycle | B29: 201 | C29: 0.089892665
A30: Basic | B30: 54 | C30: 0.024150268
A43: Marital_Status | B43: Count | C43: %
A44: Married | B44: 864 | C44: 0.38640429 | L44: Most of the customers are married.
A45: Together | B45: 578 | C45: 0.25849732
A46: Single | B46: 482 | C46: 0.21556351
A47: Divorced | B47: 231 | C47: 0.10330948
A48: Widow | B48: 77 | C48: 0.034436494
A49: Unknown | B49: 4 | C49: 0.0017889088
A62: Age_Group | B62: Average of Income_Clean
A63: Middle-aged | B63: 47637.013 | L63: Income levels are fairly consistent across age groups, with Middle-aged customers earning slightly less on average (€47,637 vs €55,644 for Seniors).
A64: Senior | B64: 55644.729
A65: Young | B65: 57882.558
A81: Category | B81: Avg Spend | C81: %
A82: MntWines | B82: =AVERAGE(MntWines) -> 304.12746 | C82: =B82/SUM(Avg_Spend_Category[Avg Spend]) -> 0.50187161
A83: MntMeatProducts | B83: =AVERAGE(MntMeatProducts) -> 166.98345 | C83: =B83/SUM(Avg_Spend_Category[Avg Spend]) -> 0.27555635 | H83: Wine dominates customer spending, accounting for nearly 50% of total product expenditure, followed by meat products.
A84: MntGoldProds | B84: =AVERAGE(MntGoldProds) -> 43.983005 | C84: =B84/SUM(Avg_Spend_Category[Avg Spend]) -> 0.072580824 | H84: Wine products should be prioritized in promotional campaigns and loyalty programs.
A85: MntFishProducts | B85: =AVERAGE(MntFishProducts) -> 37.536225 | C85: =B85/SUM(Avg_Spend_Category[Avg Spend]) -> 0.061942337
A86: MntSweetProducts | B86: =AVERAGE(MntSweetProducts) -> 27.080501 | C86: =B86/SUM(Avg_Spend_Category[Avg Spend]) -> 0.044688285
A87: MntFruits | B87: =AVERAGE(MntFruits) -> 26.275939 | C87: =B87/SUM(Avg_Spend_Category[Avg Spend]) -> 0.043360596
A103: Segment | B103: Responded | C103: %
A104: Senior + High Income | B104: =COUNTIFS(Age_Group,"Senior",Income_Segment,"High",Response,1) -> 92 | C104: =B104/(B104+B105) -> 0.77310924
A105: Middle-aged + High Income | B105: =COUNTIFS(Age_Group,"Middle-aged",Income_Segment,"Medium",Response,1) -> 27 | C105: =B105/(B104+B105) -> 0.22689076
A123: Among high-income customers, Seniors represent the dominant group (77%), making them the most valuable target audience for premium campaigns.

Sheet Campaign Analysis
A1: Who will respond to an offer for a product or service?
A3: Campaign | B3: Response Rate
A4: Campaign 4 | B4: =AVERAGE(AcceptedCmp4) -> 0.074686941
A5: Campaign 3 | B5: =AVERAGE(AcceptedCmp3) -> 0.072898032
A6: Campaign 5 | B6: =AVERAGE(AcceptedCmp5) -> 0.072450805
A7: Campaign 1 | B7: =AVERAGE(AcceptedCmp1) -> 0.064400716
A8: Campaign 2 | B8: =AVERAGE(AcceptedCmp2) -> 0.013416816
A14: Campaign 2 significantly underperformed. Campaign 4 achieved the highest response rate.
A21: Avg expenses of those who accepted the offer in the last campaign | B21: =AVERAGEIF(Response,1,TotalSpend) -> 987.39222
A22: Avg expenses of those who didn't accept the offer in the last campaign | B22: =AVERAGEIF(Response,0,TotalSpend) -> 539.00999
A24: Customers who responded spent more than twice as much as those who didn't - suggesting high-value customers are more campaign-responsive.
A26: Avg income of those who accepted the offer in the last campaign | B26: =AVERAGEIF(Response,1,Income) -> 60209.676
A27: Avg income of those who didn't accept the offer in the last campaign | B27: =AVERAGEIF(Response,0,Income) -> 50496.576
A29: Average income of those who responded is also higher.
A33: Age_Group | B33: Average of Response
A34: Young | B34: 0.23255814
A35: Middle-aged | B35: 0.15340364
A36: Senior | B36: 0.1426087
A49: Young people tend to respond better to the marketing campaign.
A52: Education | B52: Average of Response
A53: PhD | B53: 0.20824742
A54: Master | B54: 0.15405405
A55: Graduation | B55: 0.13499112
A56: 2n Cycle | B56: 0.10945274
A57: Basic | B57: 0.037037037
A67: Doctors of Philosophy respond more often to a marketing campaign.
A69: Total_Campaigns | B69: Average of Response
A70: 4 | B70: 0.90909091
A71: 3 | B71: 0.79545455
A72: 2 | B72: 0.5060241
A73: 1 | B73: 0.3117284
A74: 0 | B74: 0.082299887
A85: Customers who previously agreed to a marketing campaign, in most cases agree again.
A88: Weighted average spend of customers who accepted at least 2 campaigns:
A89: {=SUMPRODUCT((TotalCampaigns>=2)*TotalSpend) / SUMPRODUCT((TotalCampaigns>=2)*1)} -> 1510.3913

Sheet Channel Analysis
A1: Where and how do customers buy?
A3: Average of NumStorePurchases | B3: Average of NumWebPurchases | C3: Average of NumCatalogPurchases | D3: Average of NumDealsPurchases
A4: =AVERAGE(NumStorePurchases) -> 5.7956172 | B4: =AVERAGE(NumWebPurchases) -> 4.0876565 | C4: =AVERAGE(NumCatalogPurchases) -> 2.6632379 | D4: =AVERAGE(NumDealsPurchases) -> 2.3260286
D10: Physical stores remain the primary sales channel, suggesting that in-store promotions can achieve the broadest customer reach.
A22: Age_Group | B22: Average of NumWebPurchases
A23: Senior | B23: 4.4721739
A24: Middle-aged | B24: 3.6816874
A25: Young | B25: 3.6511628
A38: Surprisingly, Senior customers lead in online purchases (avg. 4.47 per period), outpacing Young customers (3.65) - suggesting digital adoption among older segments is stronger than expected.
A40: Avg of purchases made with discount by those who accepted the offer in the last campaign | B40: Avg of purchases made with discount by those who didn't accept the offer in the last campaign
A41: =AVERAGEIF(Response,1,NumDealsPurchases) -> 2.3353293 | B41: =AVERAGEIF(Response,0,NumDealsPurchases) -> 2.3243954
A48: There's almost no difference between purchases made with discount
A49: by those who responded in the last campaign and who didn't.
A53: Age_Group | B53: Average of NumWebVisitsMonth
A54: Middle-aged | B54: 5.6605944
A55: Senior | B55: 5.0417391
A56: Young | B56: 4.4418605
A61: People of middle and older age tend to visit
A62: the website more often than young people.

Sheet Dashboard Analysis
A1: Overall Response Rate (%) | B1: Response | C1: 1 | D1: Response | E1: 0 | F1: Customers in Segment | G1: Best Performing Campaign (%)
A2: 0.14937388 | F2: 2236 | G2: 0.074686941
B3: Avg. Spend of Responders ($) | D3: Avg. Spend of Responders ($)
B4: 987.39222 | D4: 539.00999
A6: Response Rate by Campaign | F6: Spend by Category | I6: Response Rate by Age Group | L6: Channel Popularity
A7: Campaign | F7: Category | I7: Age_Group | J7: Average of Response | L7: Channels
A8: Average of AcceptedCmp4 | B8: 0.074686941 | F8: Average of MntFruits | G8: 26.275939 | I8: Young | J8: 0.23255814 | L8: StorePurchases | M8: 5.7956172
A9: Average of AcceptedCmp3 | B9: 0.072898032 | F9: Average of MntSweetProducts | G9: 27.080501 | I9: Middle-aged | J9: 0.15340364 | L9: WebPurchases | M9: 4.0876565
A10: Average of AcceptedCmp5 | B10: 0.072450805 | F10: Average of MntFishProducts | G10: 37.536225 | I10: Senior | J10: 0.1426087 | L10: CatalogPurchases | M10: 2.6632379
A11: Average of AcceptedCmp1 | B11: 0.064400716 | F11: Average of MntGoldProds | G11: 43.983005 | L11: DealsPurchases | M11: 2.3260286
A12: Average of AcceptedCmp2 | B12: 0.013416816 | F12: Average of MntMeatProducts | G12: 166.98345
F13: Average of MntWines | G13: 304.12746

Sheet Dashboard
A1: Marketing Campaign Performance Analysis
A4: Customer Behavior & Response Analysis | 2,236 Customers | Dataset: Kaggle
B11: ='Dashboard Analysis'!A1 -> Overall Response Rate (%) | G11: Avg Spend: Responders vs Non-Responders ($) | L11: ='Dashboard Analysis'!F1 -> Customers in Segment | Q11: ='Dashboard Analysis'!G1 -> Best Performing Campaign (%)
C13: ='Dashboard Analysis'!A2 -> 0.14937388 | H13: ='Dashboard Analysis'!B4 -> 987.39222 | M13: ='Dashboard Analysis'!F2 -> 2236 | R13: ='Dashboard Analysis'!G2 -> 0.074686941
J15: ='Dashboard Analysis'!D4 -> 539.00999
K60: KEY INSIGHTS
B62: =CHAR(198) -> Ж | C62: High-income Seniors drive 77% of responses among top earners - priority audience for future campaigns (view diagram)
B63: =CHAR(198) -> Ж | C63: Responders spend nearly 2x more than non-responders (€987 vs €539)
B64: =CHAR(198) -> Ж | C64: Campaign 2 dramatically underperformed - 1.3% vs 7% average across all campaigns
B65: =CHAR(198) -> Ж | C65: Physical store remains the #1 purchase channel, but Seniors unexpectedly lead in online buying
